<sdf version='1.9'>
  <world name='empty'>
    <physics name='1ms' type='ignored'>
      <max_step_size>0.001</max_step_size>
      <real_time_factor>1</real_time_factor>
      <real_time_update_rate>1000</real_time_update_rate>
    </physics>
    <plugin name='gz::sim::systems::Physics' filename='ignition-gazebo-physics-system'/>
    <plugin name='gz::sim::systems::UserCommands' filename='ignition-gazebo-user-commands-system'/>
    <plugin name='gz::sim::systems::SceneBroadcaster' filename='ignition-gazebo-scene-broadcaster-system'/>
    <plugin name='gz::sim::systems::Contact' filename='ignition-gazebo-contact-system'/>
    <plugin name='gz::sim::systems::Sensors' filename='ignition-gazebo-sensors-system'/>
    <gravity>0 0 -9.8</gravity>
    <magnetic_field>6e-06 2.3e-05 -4.2e-05</magnetic_field>
    <atmosphere type='adiabatic'/>
    <scene>
      <ambient>0.4 0.4 0.4 1</ambient>
      <background>0.7 0.7 0.7 1</background>
      <shadows>true</shadows>
    </scene>
    <model name='ground_plane'>
      <static>true</static>
      <link name='link'>
        <collision name='collision'>
          <geometry>
            <plane>
              <normal>0 0 1</normal>
              <size>100 100</size>
            </plane>
          </geometry>
          <surface>
            <friction>
              <ode/>
            </friction>
            <bounce/>
            <contact/>
          </surface>
        </collision>
        <visual name='visual'>
          <geometry>
            <plane>
              <normal>0 0 1</normal>
              <size>100 100</size>
            </plane>
          </geometry>
          <material>
            <ambient>0.8 0.8 0.8 1</ambient>
            <diffuse>0.8 0.8 0.8 1</diffuse>
            <specular>0.8 0.8 0.8 1</specular>
          </material>
        </visual>
        <pose>0 0 0 0 -0 0</pose>
        <inertial>
          <pose>0 0 0 0 -0 0</pose>
          <mass>1</mass>
          <inertia>
            <ixx>1</ixx>
            <ixy>0</ixy>
            <ixz>0</ixz>
            <iyy>1</iyy>
            <iyz>0</iyz>
            <izz>1</izz>
          </inertia>
        </inertial>
        <enable_wind>false</enable_wind>
      </link>
      <pose>0 0 0 0 -0 0</pose>
      <self_collide>false</self_collide>
    </model>
    <light name='sun' type='directional'>
      <pose>0 0 10 0 -0 0</pose>
      <cast_shadows>true</cast_shadows>
      <intensity>1</intensity>
      <direction>-0.5 0.1 -0.9</direction>
      <diffuse>0.8 0.8 0.8 1</diffuse>
      <specular>0.2 0.2 0.2 1</specular>
      <attenuation>
        <range>1000</range>
        <linear>0.01</linear>
        <constant>0.90000000000000002</constant>
        <quadratic>0.001</quadratic>
      </attenuation>
      <spot>
        <inner_angle>0</inner_angle>
        <outer_angle>0</outer_angle>
        <falloff>0</falloff>
      </spot>
    </light>

    <model name="vehicle_blue" canonical_link="chassis">
      <pose relative_to="world">0 0 1 0 0 0</pose>

      <frame name="lidar_frame" attached_to="chassis">
        <pose>0.8 0 0.5 0 0 0</pose>
      </frame>

      <link name="chassis">
        <pose relative_to="__model__">0.5 0 0.4 0 0 0</pose>
        <inertial>
          <mass>1.14</mass>
          <inertia>
            <ixx>0.12</ixx>
            <ixy>0</ixy>
            <ixz>0</ixz>
            <iyy>0.41</iyy>
            <iyz>0</iyz>
            <izz>0.48</izz>
          </inertia>
        </inertial>
        <visual name="visual">
          <geometry>
            <box>
              <size>2.0 1.0 0.5</size>
            </box>
          </geometry>
          <!-- color -->
          <material>
            <ambient>0.0 0.0 1.0 1</ambient>
            <diffuse>0.0 0.0 1.0 1</diffuse>
            <specular>0.0 0.0 1.0 1</specular>
          </material>
        </visual>
        <collision name="collision">
          <geometry>
            <box>
              <size>2.0 1.0 0.5</size>
            </box>
            
          </geometry>
        </collision>
        <sensor name="gpu_lidar" type="gpu_lidar">
          <pose relative_to="lidar_frame">0 0 0 0 0 0</pose>
          <topic>lidar</topic>
          <update_rate>10</update_rate>
          <ray>
            <scan>
              <horizontal>
              <samples>640</samples>
              <resolution>1</resolution>
              <min_angle>-1.396263</min_angle>
              <max_angle>1.396263</max_angle>
              </horizontal>
              <vertical>
              <samples>1</samples>
              <resolution>0.01</resolution>
              <min_angle>0</min_angle>
              <max_angle>0</max_angle>
              </vertical>
            </scan>
            <range>
              <min>0.08</min>
              <max>10.0</max>
              <resolution>0.01</resolution>
            </range>
          </ray>
          <always_on>1</always_on>    <!-- TODO: What's this? -->
          <visualize>true</visualize>
        </sensor>
      </link>

      <!--let's build the left wheel-->
      <link name='left_wheel'>
          <pose relative_to="chassis">-0.5 0.6 0 -1.5707 0 0</pose> <!--angles are in radian-->
          <inertial>
              <mass>2</mass>
              <inertia>
                  <ixx>0.145833</ixx>
                  <ixy>0</ixy>
                  <ixz>0</ixz>
                  <iyy>0.145833</iyy>
                  <iyz>0</iyz>
                  <izz>0.125</izz>
              </inertia>
          </inertial>
          <visual name='visual'>
              <geometry>
                  <cylinder>
                      <radius>0.4</radius>
                      <length>0.2</length>
                  </cylinder>
              </geometry>
              <material>
                  <ambient>1.0 0.0 0.0 1</ambient>
                  <diffuse>1.0 0.0 0.0 1</diffuse>
                  <specular>1.0 0.0 0.0 1</specular>
              </material>
          </visual>
          <collision name='collision'>
              <geometry>
                  <cylinder>
                      <radius>0.4</radius>
                      <length>0.2</length>
                  </cylinder>
              </geometry>
          </collision>
      </link>

      <!--copy and paste for right wheel but change position-->
      <link name='right_wheel'>
          <pose relative_to="chassis">-0.5 -0.6 0 -1.5707 0 0</pose> <!--angles are in radian-->
          <inertial>
              <mass>1</mass>
              <inertia>
                  <ixx>0.145833</ixx>
                  <ixy>0</ixy>
                  <ixz>0</ixz>
                  <iyy>0.145833</iyy>
                  <iyz>0</iyz>
                  <izz>0.125</izz>
              </inertia>
          </inertial>
          <visual name='visual'>
              <geometry>
                  <cylinder>
                      <radius>0.4</radius>
                      <length>0.2</length>
                  </cylinder>
              </geometry>
              <material>
                  <ambient>1.0 0.0 0.0 1</ambient>
                  <diffuse>1.0 0.0 0.0 1</diffuse>
                  <specular>1.0 0.0 0.0 1</specular>
              </material>
          </visual>
          <collision name='collision'>
              <geometry>
                  <cylinder>
                      <radius>0.4</radius>
                      <length>0.2</length>
                  </cylinder>
              </geometry>
          </collision>
      </link>

      <frame name="caster_frame" attached_to='chassis'>
          <pose>0.8 0 -0.2 0 0 0</pose>
      </frame>

      <!--caster wheel-->
      <link name='caster'>
          <pose relative_to='caster_frame'/>
          <inertial>
              <mass>1</mass>
              <inertia>
                  <ixx>0.1</ixx>
                  <ixy>0</ixy>
                  <ixz>0</ixz>
                  <iyy>0.1</iyy>
                  <iyz>0</iyz>
                  <izz>0.1</izz>
              </inertia>
          </inertial>
          <visual name='visual'>
              <geometry>
                  <sphere>
                      <radius>0.2</radius>
                  </sphere>
              </geometry>
              <material>
                  <ambient>0.0 1 0.0 1</ambient>
                  <diffuse>0.0 1 0.0 1</diffuse>
                  <specular>0.0 1 0.0 1</specular>
              </material>
          </visual>
          <collision name='collision'>
              <geometry>
                  <sphere>
                      <radius>0.2</radius>
                  </sphere>
              </geometry>
          </collision>
      </link>

      <!--connecting these links together using joints-->
      <joint name="left_wheel_joint" type="revolute">
        <pose relative_to="left_wheel"/>
        <parent>chassis</parent>
        <child>left_wheel</child>
        <axis>
          <xyz expressed_in="__model__">0 1 0</xyz>
          <limit>
            <lower>-1.79769e+308</lower>    <!--negative infinity-->
            <upper>1.79769e+308</upper>     <!--positive infinity-->
          </limit>
        </axis>
      </joint>

      <joint name='right_wheel_joint' type='revolute'>
        <pose relative_to='right_wheel'/>
        <parent>chassis</parent>
        <child>right_wheel</child>
        <axis>
            <xyz expressed_in='__model__'>0 1 0</xyz>
            <limit>
                <lower>-1.79769e+308</lower>    <!--negative infinity-->
                <upper>1.79769e+308</upper>     <!--positive infinity-->
            </limit>
        </axis>
      </joint>

      <!--different type of joints ball joint--> <!--defult value is the child-->
      <joint name='caster_wheel' type='ball'>
          <parent>chassis</parent>
          <child>caster</child>
      </joint>

      <!--diff drive plugin-->
      <plugin
          filename="ignition-gazebo-diff-drive-system"
          name="gz::sim::systems::DiffDrive">
          <left_joint>left_wheel_joint</left_joint>
          <right_joint>right_wheel_joint</right_joint>
          <wheel_separation>1.2</wheel_separation>
          <wheel_radius>0.4</wheel_radius>
          <odom_publish_frequency>1</odom_publish_frequency>
          <topic>cmd_vel</topic>
      </plugin>
    </model>


    <!--wall-->
    <model name='wall'>
        <static>true</static>
        <pose>5 0 0 0 0 0</pose><!--pose relative to the world-->
        <link name='box'>
            <pose/>
            <inertial> <!--inertial properties of the link mass, inertia matix-->
                <mass>1.14395</mass>
                <inertia>
                    <ixx>9.532917</ixx>
                    <ixy>0</ixy>
                    <ixz>0</ixz>
                    <iyy>0.023832</iyy>
                    <iyz>0</iyz>
                    <izz>9.556749</izz>
                </inertia>
            </inertial>
            <visual name='visual'>
                <geometry>
                    <box>
                        <size>0.5 10.0 2.0</size>
                    </box>
                </geometry>
                <!--let's add color to our link-->
                <material>
                    <ambient>0.0 0.0 1.0 1</ambient>
                    <diffuse>0.0 0.0 1.0 1</diffuse>
                    <specular>0.0 0.0 1.0 1</specular>
                </material>
            </visual>
            <collision name='collision'> <!--todo: describe why we need the collision-->
                <geometry>
                    <box>
                        <size>0.5 10.0 2.0</size>
                    </box>
                </geometry>
            </collision>
            <sensor name='sensor_contact' type='contact'>
                <contact>
                    <collision>collision</collision>
                </contact>
            </sensor>
        </link>
        <plugin filename="ignition-gazebo-touchplugin-system"
                name="gz::sim::systems::TouchPlugin">
            <target>vehicle_blue</target>
            <namespace>wall</namespace>
            <time>0.001</time>
            <enabled>true</enabled>
        </plugin>
    </model>

    <!-- Moving Left-->
    <plugin filename="ignition-gazebo-triggered-publisher-system"
            name="gz::sim::systems::TriggeredPublisher">
        <input type="gz.msgs.Int32" topic="/keyboard/keypress">
            <match field="data">16777234</match>
        </input>
        <output type="gz.msgs.Twist" topic="/cmd_vel">
            linear: {x: 0.0}, angular: {z: 0.5}
        </output>
    </plugin>
    <!-- Moving Forward-->
    <plugin filename="ignition-gazebo-triggered-publisher-system"
            name="gz::sim::systems::TriggeredPublisher">
        <input type="gz.msgs.Int32" topic="/keyboard/keypress">
            <match field="data">16777235</match>
        </input>
        <output type="gz.msgs.Twist" topic="/cmd_vel">
            linear: {x: 0.5}, angular: {z: 0.0}
        </output>
    </plugin>
    <!-- Moving Right-->
    <plugin filename="ignition-gazebo-triggered-publisher-system"
            name="gz::sim::systems::TriggeredPublisher">
        <input type="gz.msgs.Int32" topic="/keyboard/keypress">
            <match field="data">16777236</match>
        </input>
        <output type="gz.msgs.Twist" topic="/cmd_vel">
            linear: {x: 0.0}, angular: {z: -0.5}
        </output>
    </plugin>
    <!-- Moving Backward-->
    <plugin filename="ignition-gazebo-triggered-publisher-system"
            name="gz::sim::systems::TriggeredPublisher">
        <input type="gz.msgs.Int32" topic="/keyboard/keypress">
            <match field="data">16777237</match>
        </input>
        <output type="gz.msgs.Twist" topic="/cmd_vel">
            linear: {x: -0.5}, angular: {z: 0.0}
        </output>
    </plugin>

    <!--stop when hit the wall-->
    <plugin filename="ignition-gazebo-triggered-publisher-system"
            name="gz::sim::systems::TriggeredPublisher">
        <input type="gz.msgs.Boolean" topic="/wall/touched">
            <match>data: true</match>
        </input>
        <output type="gz.msgs.Twist" topic="/cmd_vel">
            linear: {x: 0.0}, angular: {z: 0.0}
        </output>
    </plugin>


  </world>
</sdf>